ERROR 2021-09-21 11:15:04,830 log 33232 37080 Internal Server Error: /wallet/add_money/
Traceback (most recent call last):
  File "C:\DjangoWIS\shop_wis\lib\site-packages\django\core\handlers\exception.py", line 47, in inner
    response = get_response(request)
  File "C:\DjangoWIS\shop_wis\lib\site-packages\django\core\handlers\base.py", line 167, in _get_response
    callback, callback_args, callback_kwargs = self.resolve_request(request)
  File "C:\DjangoWIS\shop_wis\lib\site-packages\django\core\handlers\base.py", line 290, in resolve_request
    resolver_match = resolver.resolve(request.path_info)
  File "C:\DjangoWIS\shop_wis\lib\site-packages\django\urls\resolvers.py", line 558, in resolve
    sub_match = pattern.resolve(new_path)
  File "C:\DjangoWIS\shop_wis\lib\site-packages\django\urls\resolvers.py", line 558, in resolve
    sub_match = pattern.resolve(new_path)
  File "C:\DjangoWIS\shop_wis\lib\site-packages\django\urls\resolvers.py", line 362, in resolve
    kwargs.update(self.default_args)
ValueError: dictionary update sequence element #0 has length 1; 2 is required
ERROR 2021-09-21 11:18:55,296 log 37776 33444 Internal Server Error: /wallet/add_money/
Traceback (most recent call last):
  File "C:\DjangoWIS\shop_wis\lib\site-packages\django\core\handlers\exception.py", line 47, in inner
    response = get_response(request)
  File "C:\DjangoWIS\shop_wis\lib\site-packages\django\core\handlers\base.py", line 167, in _get_response
    callback, callback_args, callback_kwargs = self.resolve_request(request)
  File "C:\DjangoWIS\shop_wis\lib\site-packages\django\core\handlers\base.py", line 290, in resolve_request
    resolver_match = resolver.resolve(request.path_info)
  File "C:\DjangoWIS\shop_wis\lib\site-packages\django\urls\resolvers.py", line 558, in resolve
    sub_match = pattern.resolve(new_path)
  File "C:\DjangoWIS\shop_wis\lib\site-packages\django\urls\resolvers.py", line 558, in resolve
    sub_match = pattern.resolve(new_path)
  File "C:\DjangoWIS\shop_wis\lib\site-packages\django\urls\resolvers.py", line 362, in resolve
    kwargs.update(self.default_args)
ValueError: dictionary update sequence element #0 has length 1; 2 is required
ERROR 2021-09-21 11:19:30,563 log 31784 7472 Internal Server Error: /wallet/add_money/
Traceback (most recent call last):
  File "C:\DjangoWIS\shop_wis\lib\site-packages\django\core\handlers\exception.py", line 47, in inner
    response = get_response(request)
  File "C:\DjangoWIS\shop_wis\lib\site-packages\django\core\handlers\base.py", line 167, in _get_response
    callback, callback_args, callback_kwargs = self.resolve_request(request)
  File "C:\DjangoWIS\shop_wis\lib\site-packages\django\core\handlers\base.py", line 290, in resolve_request
    resolver_match = resolver.resolve(request.path_info)
  File "C:\DjangoWIS\shop_wis\lib\site-packages\django\urls\resolvers.py", line 558, in resolve
    sub_match = pattern.resolve(new_path)
  File "C:\DjangoWIS\shop_wis\lib\site-packages\django\urls\resolvers.py", line 558, in resolve
    sub_match = pattern.resolve(new_path)
  File "C:\DjangoWIS\shop_wis\lib\site-packages\django\urls\resolvers.py", line 362, in resolve
    kwargs.update(self.default_args)
ValueError: dictionary update sequence element #0 has length 1; 2 is required
ERROR 2021-09-21 11:19:58,254 log 31824 10848 Internal Server Error: /wallet/add_money/
Traceback (most recent call last):
  File "C:\DjangoWIS\shop_wis\lib\site-packages\django\core\handlers\exception.py", line 47, in inner
    response = get_response(request)
  File "C:\DjangoWIS\shop_wis\lib\site-packages\django\core\handlers\base.py", line 167, in _get_response
    callback, callback_args, callback_kwargs = self.resolve_request(request)
  File "C:\DjangoWIS\shop_wis\lib\site-packages\django\core\handlers\base.py", line 290, in resolve_request
    resolver_match = resolver.resolve(request.path_info)
  File "C:\DjangoWIS\shop_wis\lib\site-packages\django\urls\resolvers.py", line 558, in resolve
    sub_match = pattern.resolve(new_path)
  File "C:\DjangoWIS\shop_wis\lib\site-packages\django\urls\resolvers.py", line 558, in resolve
    sub_match = pattern.resolve(new_path)
  File "C:\DjangoWIS\shop_wis\lib\site-packages\django\urls\resolvers.py", line 362, in resolve
    kwargs.update(self.default_args)
ValueError: dictionary update sequence element #0 has length 1; 2 is required
ERROR 2021-09-21 11:22:33,575 log 12048 25576 Internal Server Error: /wallet/add_money/
Traceback (most recent call last):
  File "C:\DjangoWIS\shop_wis\lib\site-packages\django\core\handlers\exception.py", line 47, in inner
    response = get_response(request)
  File "C:\DjangoWIS\shop_wis\lib\site-packages\django\core\handlers\base.py", line 167, in _get_response
    callback, callback_args, callback_kwargs = self.resolve_request(request)
  File "C:\DjangoWIS\shop_wis\lib\site-packages\django\core\handlers\base.py", line 290, in resolve_request
    resolver_match = resolver.resolve(request.path_info)
  File "C:\DjangoWIS\shop_wis\lib\site-packages\django\urls\resolvers.py", line 558, in resolve
    sub_match = pattern.resolve(new_path)
  File "C:\DjangoWIS\shop_wis\lib\site-packages\django\urls\resolvers.py", line 558, in resolve
    sub_match = pattern.resolve(new_path)
  File "C:\DjangoWIS\shop_wis\lib\site-packages\django\urls\resolvers.py", line 362, in resolve
    kwargs.update(self.default_args)
ValueError: dictionary update sequence element #0 has length 1; 2 is required
ERROR 2021-09-21 12:08:36,203 log 31900 25596 Internal Server Error: /wallet/add_money/
Traceback (most recent call last):
  File "C:\DjangoWIS\shop_wis\lib\site-packages\django\core\handlers\exception.py", line 47, in inner
    response = get_response(request)
  File "C:\DjangoWIS\shop_wis\lib\site-packages\django\core\handlers\base.py", line 204, in _get_response
    response = response.render()
  File "C:\DjangoWIS\shop_wis\lib\site-packages\django\template\response.py", line 105, in render
    self.content = self.rendered_content
  File "C:\DjangoWIS\shop_wis\lib\site-packages\django\template\response.py", line 83, in rendered_content
    return template.render(context, self._request)
  File "C:\DjangoWIS\shop_wis\lib\site-packages\django\template\backends\django.py", line 61, in render
    return self.template.render(context)
  File "C:\DjangoWIS\shop_wis\lib\site-packages\django\template\base.py", line 170, in render
    return self._render(context)
  File "C:\DjangoWIS\shop_wis\lib\site-packages\django\template\base.py", line 162, in _render
    return self.nodelist.render(context)
  File "C:\DjangoWIS\shop_wis\lib\site-packages\django\template\base.py", line 938, in render
    bit = node.render_annotated(context)
  File "C:\DjangoWIS\shop_wis\lib\site-packages\django\template\base.py", line 905, in render_annotated
    return self.render(context)
  File "C:\DjangoWIS\shop_wis\lib\site-packages\django\template\defaulttags.py", line 446, in render
    url = reverse(view_name, args=args, kwargs=kwargs, current_app=current_app)
  File "C:\DjangoWIS\shop_wis\lib\site-packages\django\urls\base.py", line 86, in reverse
    return resolver._reverse_with_prefix(view, prefix, *args, **kwargs)
  File "C:\DjangoWIS\shop_wis\lib\site-packages\django\urls\resolvers.py", line 694, in _reverse_with_prefix
    raise NoReverseMatch(msg)
django.urls.exceptions.NoReverseMatch: Reverse for 'add_money' not found. 'add_money' is not a valid view function or pattern name.
ERROR 2021-09-21 12:18:56,973 log 5188 37772 Internal Server Error: /wallet/add_money/
Traceback (most recent call last):
  File "C:\DjangoWIS\shop_wis\lib\site-packages\django\core\handlers\exception.py", line 47, in inner
    response = get_response(request)
  File "C:\DjangoWIS\shop_wis\lib\site-packages\django\core\handlers\base.py", line 181, in _get_response
    response = wrapped_callback(request, *callback_args, **callback_kwargs)
  File "C:\DjangoWIS\shop_wis\lib\site-packages\django\views\generic\base.py", line 70, in view
    return self.dispatch(request, *args, **kwargs)
  File "C:\DjangoWIS\shop_wis\lib\site-packages\django\contrib\auth\mixins.py", line 104, in dispatch
    return super().dispatch(request, *args, **kwargs)
  File "C:\DjangoWIS\shop_wis\lib\site-packages\django\views\generic\base.py", line 98, in dispatch
    return handler(request, *args, **kwargs)
  File "C:\DjangoWIS\ashtray\purse\views.py", line 29, in post
    print(form.cleaned_data)
AttributeError: 'AddMoneyForm' object has no attribute 'cleaned_data'
ERROR 2021-09-21 12:23:53,050 log 524 14248 Internal Server Error: /wallet/add_money/
Traceback (most recent call last):
  File "C:\DjangoWIS\shop_wis\lib\site-packages\django\core\handlers\exception.py", line 47, in inner
    response = get_response(request)
  File "C:\DjangoWIS\shop_wis\lib\site-packages\django\core\handlers\base.py", line 188, in _get_response
    self.check_response(response, callback)
  File "C:\DjangoWIS\shop_wis\lib\site-packages\django\core\handlers\base.py", line 311, in check_response
    "instead." % name
ValueError: The view purse.views.AddWalletView didn't return an HttpResponse object. It returned None instead.
ERROR 2021-09-21 12:24:32,848 log 33496 33684 Internal Server Error: /wallet/add_money/
Traceback (most recent call last):
  File "C:\DjangoWIS\shop_wis\lib\site-packages\django\core\handlers\exception.py", line 47, in inner
    response = get_response(request)
  File "C:\DjangoWIS\shop_wis\lib\site-packages\django\core\handlers\base.py", line 188, in _get_response
    self.check_response(response, callback)
  File "C:\DjangoWIS\shop_wis\lib\site-packages\django\core\handlers\base.py", line 311, in check_response
    "instead." % name
ValueError: The view purse.views.AddWalletView didn't return an HttpResponse object. It returned None instead.
ERROR 2021-09-21 12:37:28,605 log 37336 18092 Internal Server Error: /wallet/add_money/
Traceback (most recent call last):
  File "C:\DjangoWIS\shop_wis\lib\site-packages\django\core\handlers\exception.py", line 47, in inner
    response = get_response(request)
  File "C:\DjangoWIS\shop_wis\lib\site-packages\django\core\handlers\base.py", line 181, in _get_response
    response = wrapped_callback(request, *callback_args, **callback_kwargs)
  File "C:\DjangoWIS\shop_wis\lib\site-packages\django\views\generic\base.py", line 70, in view
    return self.dispatch(request, *args, **kwargs)
  File "C:\DjangoWIS\shop_wis\lib\site-packages\django\contrib\auth\mixins.py", line 104, in dispatch
    return super().dispatch(request, *args, **kwargs)
  File "C:\DjangoWIS\shop_wis\lib\site-packages\django\views\generic\base.py", line 98, in dispatch
    return handler(request, *args, **kwargs)
  File "C:\DjangoWIS\ashtray\purse\views.py", line 30, in post
    print(form.cleaned_data)
AttributeError: 'AddMoneyForm' object has no attribute 'cleaned_data'
ERROR 2021-09-21 12:38:24,529 log 37336 18092 Internal Server Error: /wallet/add_money/
Traceback (most recent call last):
  File "C:\DjangoWIS\shop_wis\lib\site-packages\django\core\handlers\exception.py", line 47, in inner
    response = get_response(request)
  File "C:\DjangoWIS\shop_wis\lib\site-packages\django\core\handlers\base.py", line 181, in _get_response
    response = wrapped_callback(request, *callback_args, **callback_kwargs)
  File "C:\DjangoWIS\shop_wis\lib\site-packages\django\views\generic\base.py", line 70, in view
    return self.dispatch(request, *args, **kwargs)
  File "C:\DjangoWIS\shop_wis\lib\site-packages\django\contrib\auth\mixins.py", line 104, in dispatch
    return super().dispatch(request, *args, **kwargs)
  File "C:\DjangoWIS\shop_wis\lib\site-packages\django\views\generic\base.py", line 98, in dispatch
    return handler(request, *args, **kwargs)
  File "C:\DjangoWIS\ashtray\purse\views.py", line 30, in post
    print(form.cleaned_data)
AttributeError: 'AddMoneyForm' object has no attribute 'cleaned_data'
ERROR 2021-09-21 12:39:28,299 log 16524 33808 Internal Server Error: /wallet/add_money/
Traceback (most recent call last):
  File "C:\DjangoWIS\shop_wis\lib\site-packages\django\core\handlers\exception.py", line 47, in inner
    response = get_response(request)
  File "C:\DjangoWIS\shop_wis\lib\site-packages\django\core\handlers\base.py", line 181, in _get_response
    response = wrapped_callback(request, *callback_args, **callback_kwargs)
  File "C:\DjangoWIS\shop_wis\lib\site-packages\django\views\generic\base.py", line 70, in view
    return self.dispatch(request, *args, **kwargs)
  File "C:\DjangoWIS\shop_wis\lib\site-packages\django\views\generic\base.py", line 98, in dispatch
    return handler(request, *args, **kwargs)
  File "C:\DjangoWIS\ashtray\purse\views.py", line 30, in post
    print(form.cleaned_data)
AttributeError: 'AddMoneyForm' object has no attribute 'cleaned_data'
ERROR 2021-09-21 12:40:45,824 log 26392 27752 Internal Server Error: /wallet/add_money/
Traceback (most recent call last):
  File "C:\DjangoWIS\shop_wis\lib\site-packages\django\core\handlers\exception.py", line 47, in inner
    response = get_response(request)
  File "C:\DjangoWIS\shop_wis\lib\site-packages\django\core\handlers\base.py", line 181, in _get_response
    response = wrapped_callback(request, *callback_args, **callback_kwargs)
  File "C:\DjangoWIS\shop_wis\lib\site-packages\django\views\generic\base.py", line 70, in view
    return self.dispatch(request, *args, **kwargs)
  File "C:\DjangoWIS\shop_wis\lib\site-packages\django\views\generic\base.py", line 98, in dispatch
    return handler(request, *args, **kwargs)
  File "C:\DjangoWIS\ashtray\purse\views.py", line 30, in post
    cd = form.cleaned_data
AttributeError: 'AddMoneyForm' object has no attribute 'cleaned_data'
ERROR 2021-09-21 12:43:25,966 log 19968 31772 Internal Server Error: /wallet/add_money/
Traceback (most recent call last):
  File "C:\DjangoWIS\shop_wis\lib\site-packages\django\core\handlers\exception.py", line 47, in inner
    response = get_response(request)
  File "C:\DjangoWIS\shop_wis\lib\site-packages\django\core\handlers\base.py", line 181, in _get_response
    response = wrapped_callback(request, *callback_args, **callback_kwargs)
  File "C:\DjangoWIS\shop_wis\lib\site-packages\django\views\generic\base.py", line 70, in view
    return self.dispatch(request, *args, **kwargs)
  File "C:\DjangoWIS\shop_wis\lib\site-packages\django\views\generic\base.py", line 98, in dispatch
    return handler(request, *args, **kwargs)
  File "C:\DjangoWIS\ashtray\purse\views.py", line 30, in post
    cd = form.cleaned_data
AttributeError: 'AddMoneyForm' object has no attribute 'cleaned_data'
ERROR 2021-09-21 12:54:23,185 log 21052 9984 Internal Server Error: /wallet/add_money/
Traceback (most recent call last):
  File "C:\DjangoWIS\shop_wis\lib\site-packages\django\core\handlers\exception.py", line 47, in inner
    response = get_response(request)
  File "C:\DjangoWIS\shop_wis\lib\site-packages\django\core\handlers\base.py", line 181, in _get_response
    response = wrapped_callback(request, *callback_args, **callback_kwargs)
  File "C:\DjangoWIS\shop_wis\lib\site-packages\django\views\generic\base.py", line 70, in view
    return self.dispatch(request, *args, **kwargs)
  File "C:\DjangoWIS\shop_wis\lib\site-packages\django\views\generic\base.py", line 98, in dispatch
    return handler(request, *args, **kwargs)
  File "C:\DjangoWIS\ashtray\purse\views.py", line 31, in post
    form = AddMoneyForm(user_id=user, money=request.POST.get('money'))
  File "C:\DjangoWIS\ashtray\purse\forms.py", line 12, in __init__
    super(AddMoneyForm, self).__init__(*args, **kwargs)
TypeError: __init__() got an unexpected keyword argument 'user_id'
ERROR 2021-09-21 12:54:57,060 log 2764 32808 Internal Server Error: /wallet/add_money/
Traceback (most recent call last):
  File "C:\DjangoWIS\shop_wis\lib\site-packages\django\core\handlers\exception.py", line 47, in inner
    response = get_response(request)
  File "C:\DjangoWIS\shop_wis\lib\site-packages\django\core\handlers\base.py", line 181, in _get_response
    response = wrapped_callback(request, *callback_args, **callback_kwargs)
  File "C:\DjangoWIS\shop_wis\lib\site-packages\django\views\generic\base.py", line 70, in view
    return self.dispatch(request, *args, **kwargs)
  File "C:\DjangoWIS\shop_wis\lib\site-packages\django\views\generic\base.py", line 98, in dispatch
    return handler(request, *args, **kwargs)
  File "C:\DjangoWIS\ashtray\purse\views.py", line 39, in post
    user_wallet.money += cd['money']
AttributeError: 'tuple' object has no attribute 'money'
ERROR 2021-09-21 12:54:58,527 log 2764 32808 Internal Server Error: /wallet/add_money/
Traceback (most recent call last):
  File "C:\DjangoWIS\shop_wis\lib\site-packages\django\core\handlers\exception.py", line 47, in inner
    response = get_response(request)
  File "C:\DjangoWIS\shop_wis\lib\site-packages\django\core\handlers\base.py", line 181, in _get_response
    response = wrapped_callback(request, *callback_args, **callback_kwargs)
  File "C:\DjangoWIS\shop_wis\lib\site-packages\django\views\generic\base.py", line 70, in view
    return self.dispatch(request, *args, **kwargs)
  File "C:\DjangoWIS\shop_wis\lib\site-packages\django\views\generic\base.py", line 98, in dispatch
    return handler(request, *args, **kwargs)
  File "C:\DjangoWIS\ashtray\purse\views.py", line 39, in post
    user_wallet.money += cd['money']
AttributeError: 'tuple' object has no attribute 'money'
ERROR 2021-09-21 13:38:26,577 log 29388 39848 Internal Server Error: /wallet/add_money/
Traceback (most recent call last):
  File "C:\DjangoWIS\shop_wis\lib\site-packages\django\core\handlers\exception.py", line 47, in inner
    response = get_response(request)
  File "C:\DjangoWIS\shop_wis\lib\site-packages\django\core\handlers\base.py", line 181, in _get_response
    response = wrapped_callback(request, *callback_args, **callback_kwargs)
  File "C:\DjangoWIS\shop_wis\lib\site-packages\django\views\generic\base.py", line 70, in view
    return self.dispatch(request, *args, **kwargs)
  File "C:\DjangoWIS\shop_wis\lib\site-packages\django\views\generic\base.py", line 98, in dispatch
    return handler(request, *args, **kwargs)
  File "C:\DjangoWIS\ashtray\purse\views.py", line 35, in post
    user_wallet.money += cd['money']
AttributeError: 'tuple' object has no attribute 'money'
ERROR 2021-09-21 13:39:15,993 log 40948 24672 Internal Server Error: /wallet/add_money/
Traceback (most recent call last):
  File "C:\DjangoWIS\shop_wis\lib\site-packages\django\core\handlers\exception.py", line 47, in inner
    response = get_response(request)
  File "C:\DjangoWIS\shop_wis\lib\site-packages\django\core\handlers\base.py", line 181, in _get_response
    response = wrapped_callback(request, *callback_args, **callback_kwargs)
  File "C:\DjangoWIS\shop_wis\lib\site-packages\django\views\generic\base.py", line 70, in view
    return self.dispatch(request, *args, **kwargs)
  File "C:\DjangoWIS\shop_wis\lib\site-packages\django\views\generic\base.py", line 98, in dispatch
    return handler(request, *args, **kwargs)
  File "C:\DjangoWIS\ashtray\purse\views.py", line 36, in post
    user_wallet.money += cd['money']
AttributeError: 'tuple' object has no attribute 'money'
ERROR 2021-09-21 13:39:47,246 log 32532 40424 Internal Server Error: /wallet/add_money/
Traceback (most recent call last):
  File "C:\DjangoWIS\shop_wis\lib\site-packages\django\core\handlers\exception.py", line 47, in inner
    response = get_response(request)
  File "C:\DjangoWIS\shop_wis\lib\site-packages\django\core\handlers\base.py", line 181, in _get_response
    response = wrapped_callback(request, *callback_args, **callback_kwargs)
  File "C:\DjangoWIS\shop_wis\lib\site-packages\django\views\generic\base.py", line 70, in view
    return self.dispatch(request, *args, **kwargs)
  File "C:\DjangoWIS\shop_wis\lib\site-packages\django\views\generic\base.py", line 98, in dispatch
    return handler(request, *args, **kwargs)
  File "C:\DjangoWIS\ashtray\purse\views.py", line 35, in post
    user_wallet = PurseModel.objects.get_or_create(user_id=cd['user_id']).first()
AttributeError: 'tuple' object has no attribute 'first'
ERROR 2021-09-21 13:45:29,272 log 35860 40196 Internal Server Error: /wallet/add_money/
Traceback (most recent call last):
  File "C:\DjangoWIS\shop_wis\lib\site-packages\django\core\handlers\exception.py", line 47, in inner
    response = get_response(request)
  File "C:\DjangoWIS\shop_wis\lib\site-packages\django\core\handlers\base.py", line 181, in _get_response
    response = wrapped_callback(request, *callback_args, **callback_kwargs)
  File "C:\DjangoWIS\shop_wis\lib\site-packages\django\views\generic\base.py", line 70, in view
    return self.dispatch(request, *args, **kwargs)
  File "C:\DjangoWIS\shop_wis\lib\site-packages\django\views\generic\base.py", line 98, in dispatch
    return handler(request, *args, **kwargs)
  File "C:\DjangoWIS\ashtray\purse\views.py", line 40, in post
    return HttpResponseRedirect(reverse('wallet:money' 'done'))
  File "C:\DjangoWIS\shop_wis\lib\site-packages\django\urls\base.py", line 86, in reverse
    return resolver._reverse_with_prefix(view, prefix, *args, **kwargs)
  File "C:\DjangoWIS\shop_wis\lib\site-packages\django\urls\resolvers.py", line 694, in _reverse_with_prefix
    raise NoReverseMatch(msg)
django.urls.exceptions.NoReverseMatch: Reverse for 'moneydone' not found. 'moneydone' is not a valid view function or pattern name.
ERROR 2021-09-21 13:47:01,871 log 39692 40772 Internal Server Error: /wallet/add_money/
Traceback (most recent call last):
  File "C:\DjangoWIS\shop_wis\lib\site-packages\django\core\handlers\exception.py", line 47, in inner
    response = get_response(request)
  File "C:\DjangoWIS\shop_wis\lib\site-packages\django\core\handlers\base.py", line 181, in _get_response
    response = wrapped_callback(request, *callback_args, **callback_kwargs)
  File "C:\DjangoWIS\shop_wis\lib\site-packages\django\views\generic\base.py", line 70, in view
    return self.dispatch(request, *args, **kwargs)
  File "C:\DjangoWIS\shop_wis\lib\site-packages\django\views\generic\base.py", line 98, in dispatch
    return handler(request, *args, **kwargs)
  File "C:\DjangoWIS\ashtray\purse\views.py", line 40, in post
    return HttpResponseRedirect(reverse('wallet:money', kwargs={'message': 'done'}))
  File "C:\DjangoWIS\shop_wis\lib\site-packages\django\urls\base.py", line 86, in reverse
    return resolver._reverse_with_prefix(view, prefix, *args, **kwargs)
  File "C:\DjangoWIS\shop_wis\lib\site-packages\django\urls\resolvers.py", line 694, in _reverse_with_prefix
    raise NoReverseMatch(msg)
django.urls.exceptions.NoReverseMatch: Reverse for 'money' with keyword arguments '{'message': 'done'}' not found. 1 pattern(s) tried: ['wallet\\/add_money\\/$']
ERROR 2021-09-21 13:48:12,829 log 36340 20424 Internal Server Error: /wallet/add_money/
Traceback (most recent call last):
  File "C:\DjangoWIS\shop_wis\lib\site-packages\django\core\handlers\exception.py", line 47, in inner
    response = get_response(request)
  File "C:\DjangoWIS\shop_wis\lib\site-packages\django\core\handlers\base.py", line 181, in _get_response
    response = wrapped_callback(request, *callback_args, **callback_kwargs)
  File "C:\DjangoWIS\shop_wis\lib\site-packages\django\views\generic\base.py", line 70, in view
    return self.dispatch(request, *args, **kwargs)
  File "C:\DjangoWIS\shop_wis\lib\site-packages\django\views\generic\base.py", line 98, in dispatch
    return handler(request, *args, **kwargs)
  File "C:\DjangoWIS\ashtray\purse\views.py", line 40, in post
    return HttpResponseRedirect(reverse('wallet:money', args=['done']))
  File "C:\DjangoWIS\shop_wis\lib\site-packages\django\urls\base.py", line 86, in reverse
    return resolver._reverse_with_prefix(view, prefix, *args, **kwargs)
  File "C:\DjangoWIS\shop_wis\lib\site-packages\django\urls\resolvers.py", line 694, in _reverse_with_prefix
    raise NoReverseMatch(msg)
django.urls.exceptions.NoReverseMatch: Reverse for 'money' with arguments '('done',)' not found. 1 pattern(s) tried: ['wallet\\/add_money\\/$']
ERROR 2021-09-21 13:48:27,356 log 30528 35064 Internal Server Error: /wallet/add_money/
Traceback (most recent call last):
  File "C:\DjangoWIS\shop_wis\lib\site-packages\django\core\handlers\exception.py", line 47, in inner
    response = get_response(request)
  File "C:\DjangoWIS\shop_wis\lib\site-packages\django\core\handlers\base.py", line 181, in _get_response
    response = wrapped_callback(request, *callback_args, **callback_kwargs)
  File "C:\DjangoWIS\shop_wis\lib\site-packages\django\views\generic\base.py", line 70, in view
    return self.dispatch(request, *args, **kwargs)
  File "C:\DjangoWIS\shop_wis\lib\site-packages\django\views\generic\base.py", line 98, in dispatch
    return handler(request, *args, **kwargs)
  File "C:\DjangoWIS\ashtray\purse\views.py", line 40, in post
    return HttpResponseRedirect(reverse('wallet:money', args=['done',]))
  File "C:\DjangoWIS\shop_wis\lib\site-packages\django\urls\base.py", line 86, in reverse
    return resolver._reverse_with_prefix(view, prefix, *args, **kwargs)
  File "C:\DjangoWIS\shop_wis\lib\site-packages\django\urls\resolvers.py", line 694, in _reverse_with_prefix
    raise NoReverseMatch(msg)
django.urls.exceptions.NoReverseMatch: Reverse for 'money' with arguments '('done',)' not found. 1 pattern(s) tried: ['wallet\\/add_money\\/$']
ERROR 2021-09-21 13:49:25,694 log 32868 39836 Internal Server Error: /wallet/add_money/
Traceback (most recent call last):
  File "C:\DjangoWIS\shop_wis\lib\site-packages\django\core\handlers\exception.py", line 47, in inner
    response = get_response(request)
  File "C:\DjangoWIS\shop_wis\lib\site-packages\django\core\handlers\base.py", line 181, in _get_response
    response = wrapped_callback(request, *callback_args, **callback_kwargs)
  File "C:\DjangoWIS\shop_wis\lib\site-packages\django\views\generic\base.py", line 70, in view
    return self.dispatch(request, *args, **kwargs)
  File "C:\DjangoWIS\shop_wis\lib\site-packages\django\views\generic\base.py", line 98, in dispatch
    return handler(request, *args, **kwargs)
  File "C:\DjangoWIS\ashtray\purse\views.py", line 40, in post
    return HttpResponseRedirect(reverse('wallet:money', message='done'))
TypeError: reverse() got an unexpected keyword argument 'message'
ERROR 2021-09-21 13:49:38,966 log 40256 19840 Internal Server Error: /wallet/add_money/
Traceback (most recent call last):
  File "C:\DjangoWIS\shop_wis\lib\site-packages\django\core\handlers\exception.py", line 47, in inner
    response = get_response(request)
  File "C:\DjangoWIS\shop_wis\lib\site-packages\django\core\handlers\base.py", line 181, in _get_response
    response = wrapped_callback(request, *callback_args, **callback_kwargs)
  File "C:\DjangoWIS\shop_wis\lib\site-packages\django\views\generic\base.py", line 70, in view
    return self.dispatch(request, *args, **kwargs)
  File "C:\DjangoWIS\shop_wis\lib\site-packages\django\views\generic\base.py", line 98, in dispatch
    return handler(request, *args, **kwargs)
  File "C:\DjangoWIS\ashtray\purse\views.py", line 40, in post
    return HttpResponseRedirect(reverse('wallet:money', 'done'))
  File "C:\DjangoWIS\shop_wis\lib\site-packages\django\urls\base.py", line 54, in reverse
    app_list = resolver.app_dict[ns]
  File "C:\DjangoWIS\shop_wis\lib\site-packages\django\urls\resolvers.py", line 526, in app_dict
    self._populate()
  File "C:\DjangoWIS\shop_wis\lib\site-packages\django\urls\resolvers.py", line 460, in _populate
    for url_pattern in reversed(self.url_patterns):
  File "C:\DjangoWIS\shop_wis\lib\site-packages\django\utils\functional.py", line 48, in __get__
    res = instance.__dict__[self.name] = self.func(instance)
  File "C:\DjangoWIS\shop_wis\lib\site-packages\django\urls\resolvers.py", line 598, in url_patterns
    patterns = getattr(self.urlconf_module, "urlpatterns", self.urlconf_module)
  File "C:\DjangoWIS\shop_wis\lib\site-packages\django\utils\functional.py", line 48, in __get__
    res = instance.__dict__[self.name] = self.func(instance)
  File "C:\DjangoWIS\shop_wis\lib\site-packages\django\urls\resolvers.py", line 591, in urlconf_module
    return import_module(self.urlconf_name)
  File "C:\Program Files\Python36\lib\importlib\__init__.py", line 126, in import_module
    return _bootstrap._gcd_import(name[level:], package, level)
  File "<frozen importlib._bootstrap>", line 994, in _gcd_import
  File "<frozen importlib._bootstrap>", line 971, in _find_and_load
  File "<frozen importlib._bootstrap>", line 953, in _find_and_load_unlocked
ModuleNotFoundError: No module named 'done'
ERROR 2021-09-21 13:50:12,831 log 25048 16024 Internal Server Error: /wallet/add_money/
Traceback (most recent call last):
  File "C:\DjangoWIS\shop_wis\lib\site-packages\django\core\handlers\exception.py", line 47, in inner
    response = get_response(request)
  File "C:\DjangoWIS\shop_wis\lib\site-packages\django\core\handlers\base.py", line 181, in _get_response
    response = wrapped_callback(request, *callback_args, **callback_kwargs)
  File "C:\DjangoWIS\shop_wis\lib\site-packages\django\views\generic\base.py", line 70, in view
    return self.dispatch(request, *args, **kwargs)
  File "C:\DjangoWIS\shop_wis\lib\site-packages\django\views\generic\base.py", line 98, in dispatch
    return handler(request, *args, **kwargs)
  File "C:\DjangoWIS\ashtray\purse\views.py", line 40, in post
    return HttpResponseRedirect(reverse('wallet:money', {'message':'done'}))
  File "C:\DjangoWIS\shop_wis\lib\site-packages\django\urls\base.py", line 30, in reverse
    resolver = get_resolver(urlconf)
  File "C:\DjangoWIS\shop_wis\lib\site-packages\django\urls\resolvers.py", line 71, in get_resolver
    return _get_cached_resolver(urlconf)
TypeError: unhashable type: 'dict'
ERROR 2021-09-21 13:50:24,231 log 31528 39972 Internal Server Error: /wallet/add_money/
Traceback (most recent call last):
  File "C:\DjangoWIS\shop_wis\lib\site-packages\django\core\handlers\exception.py", line 47, in inner
    response = get_response(request)
  File "C:\DjangoWIS\shop_wis\lib\site-packages\django\core\handlers\base.py", line 181, in _get_response
    response = wrapped_callback(request, *callback_args, **callback_kwargs)
  File "C:\DjangoWIS\shop_wis\lib\site-packages\django\views\generic\base.py", line 70, in view
    return self.dispatch(request, *args, **kwargs)
  File "C:\DjangoWIS\shop_wis\lib\site-packages\django\views\generic\base.py", line 98, in dispatch
    return handler(request, *args, **kwargs)
  File "C:\DjangoWIS\ashtray\purse\views.py", line 40, in post
    return HttpResponseRedirect(reverse('wallet:money', args={'message':'done'}))
  File "C:\DjangoWIS\shop_wis\lib\site-packages\django\urls\base.py", line 86, in reverse
    return resolver._reverse_with_prefix(view, prefix, *args, **kwargs)
  File "C:\DjangoWIS\shop_wis\lib\site-packages\django\urls\resolvers.py", line 694, in _reverse_with_prefix
    raise NoReverseMatch(msg)
django.urls.exceptions.NoReverseMatch: Reverse for 'money' with arguments '('message',)' not found. 1 pattern(s) tried: ['wallet\\/add_money\\/$']
ERROR 2021-09-21 13:52:16,444 log 19076 27104 Internal Server Error: /wallet/add_money/
Traceback (most recent call last):
  File "C:\DjangoWIS\shop_wis\lib\site-packages\django\core\handlers\exception.py", line 47, in inner
    response = get_response(request)
  File "C:\DjangoWIS\shop_wis\lib\site-packages\django\core\handlers\base.py", line 181, in _get_response
    response = wrapped_callback(request, *callback_args, **callback_kwargs)
  File "C:\DjangoWIS\shop_wis\lib\site-packages\django\views\generic\base.py", line 70, in view
    return self.dispatch(request, *args, **kwargs)
  File "C:\DjangoWIS\shop_wis\lib\site-packages\django\views\generic\base.py", line 98, in dispatch
    return handler(request, *args, **kwargs)
  File "C:\DjangoWIS\ashtray\purse\views.py", line 39, in post
    return HttpResponseRedirect(reverse('wallet:money', kwargs={'mes':'done'}))
  File "C:\DjangoWIS\shop_wis\lib\site-packages\django\urls\base.py", line 86, in reverse
    return resolver._reverse_with_prefix(view, prefix, *args, **kwargs)
  File "C:\DjangoWIS\shop_wis\lib\site-packages\django\urls\resolvers.py", line 694, in _reverse_with_prefix
    raise NoReverseMatch(msg)
django.urls.exceptions.NoReverseMatch: Reverse for 'money' with keyword arguments '{'mes': 'done'}' not found. 1 pattern(s) tried: ['wallet\\/add_money\\/$']
ERROR 2021-09-21 14:23:00,510 log 38992 36380 Internal Server Error: /wallet/add_money/
Traceback (most recent call last):
  File "C:\DjangoWIS\shop_wis\lib\site-packages\django\core\handlers\exception.py", line 47, in inner
    response = get_response(request)
  File "C:\DjangoWIS\shop_wis\lib\site-packages\django\core\handlers\base.py", line 181, in _get_response
    response = wrapped_callback(request, *callback_args, **callback_kwargs)
  File "C:\DjangoWIS\shop_wis\lib\site-packages\django\views\generic\base.py", line 70, in view
    return self.dispatch(request, *args, **kwargs)
  File "C:\DjangoWIS\shop_wis\lib\site-packages\django\views\generic\base.py", line 98, in dispatch
    return handler(request, *args, **kwargs)
  File "C:\DjangoWIS\ashtray\purse\views.py", line 52, in post
    return self.get(request, *args, **kwargs)
  File "C:\DjangoWIS\ashtray\purse\views.py", line 31, in get
    if kwargs['message']:
KeyError: 'message'
